[2022-09-12T15:00:49.284+0000] {taskinstance.py:1171} INFO - Dependencies all met for <TaskInstance: first_dag.get_data manual__2022-09-12T15:00:47.119022+00:00 [queued]>
[2022-09-12T15:00:49.303+0000] {taskinstance.py:1171} INFO - Dependencies all met for <TaskInstance: first_dag.get_data manual__2022-09-12T15:00:47.119022+00:00 [queued]>
[2022-09-12T15:00:49.304+0000] {taskinstance.py:1368} INFO - 
--------------------------------------------------------------------------------
[2022-09-12T15:00:49.305+0000] {taskinstance.py:1369} INFO - Starting attempt 1 of 2
[2022-09-12T15:00:49.306+0000] {taskinstance.py:1370} INFO - 
--------------------------------------------------------------------------------
[2022-09-12T15:00:49.329+0000] {taskinstance.py:1389} INFO - Executing <Task(PythonOperator): get_data> on 2022-09-12 15:00:47.119022+00:00
[2022-09-12T15:00:49.338+0000] {standard_task_runner.py:52} INFO - Started process 229 to run task
[2022-09-12T15:00:49.344+0000] {standard_task_runner.py:79} INFO - Running: ['***', 'tasks', 'run', 'first_dag', 'get_data', 'manual__2022-09-12T15:00:47.119022+00:00', '--job-id', '38', '--raw', '--subdir', 'DAGS_FOLDER/first_dag.py', '--cfg-path', '/tmp/tmpqb7fspwe', '--error-file', '/tmp/tmpak28tsyc']
[2022-09-12T15:00:49.346+0000] {standard_task_runner.py:80} INFO - Job 38: Subtask get_data
[2022-09-12T15:00:49.456+0000] {task_command.py:371} INFO - Running <TaskInstance: first_dag.get_data manual__2022-09-12T15:00:47.119022+00:00 [running]> on host 657cf21911db
[2022-09-12T15:00:49.581+0000] {taskinstance.py:1583} INFO - Exporting the following env vars:
AIRFLOW_CTX_DAG_OWNER=***
AIRFLOW_CTX_DAG_ID=first_dag
AIRFLOW_CTX_TASK_ID=get_data
AIRFLOW_CTX_EXECUTION_DATE=2022-09-12T15:00:47.119022+00:00
AIRFLOW_CTX_TRY_NUMBER=1
AIRFLOW_CTX_DAG_RUN_ID=manual__2022-09-12T15:00:47.119022+00:00
[2022-09-12T15:00:49.583+0000] {logging_mixin.py:115} INFO - Hello waw... Tom, 4
[2022-09-12T15:00:49.586+0000] {taskinstance.py:1902} ERROR - Task failed with exception
Traceback (most recent call last):
  File "/home/airflow/.local/lib/python3.7/site-packages/airflow/operators/python.py", line 171, in execute
    return_value = self.execute_callable()
  File "/home/airflow/.local/lib/python3.7/site-packages/airflow/operators/python.py", line 189, in execute_callable
    return self.python_callable(*self.op_args, **self.op_kwargs)
  File "/opt/airflow/dags/first_dag.py", line 19, in get_data
    apps = pd.read_csv('data/DATA.csv')
  File "/home/airflow/.local/lib/python3.7/site-packages/pandas/util/_decorators.py", line 311, in wrapper
    return func(*args, **kwargs)
  File "/home/airflow/.local/lib/python3.7/site-packages/pandas/io/parsers/readers.py", line 586, in read_csv
    return _read(filepath_or_buffer, kwds)
  File "/home/airflow/.local/lib/python3.7/site-packages/pandas/io/parsers/readers.py", line 482, in _read
    parser = TextFileReader(filepath_or_buffer, **kwds)
  File "/home/airflow/.local/lib/python3.7/site-packages/pandas/io/parsers/readers.py", line 811, in __init__
    self._engine = self._make_engine(self.engine)
  File "/home/airflow/.local/lib/python3.7/site-packages/pandas/io/parsers/readers.py", line 1040, in _make_engine
    return mapping[engine](self.f, **self.options)  # type: ignore[call-arg]
  File "/home/airflow/.local/lib/python3.7/site-packages/pandas/io/parsers/c_parser_wrapper.py", line 51, in __init__
    self._open_handles(src, kwds)
  File "/home/airflow/.local/lib/python3.7/site-packages/pandas/io/parsers/base_parser.py", line 229, in _open_handles
    errors=kwds.get("encoding_errors", "strict"),
  File "/home/airflow/.local/lib/python3.7/site-packages/pandas/io/common.py", line 707, in get_handle
    newline="",
FileNotFoundError: [Errno 2] No such file or directory: 'data/DATA.csv'
[2022-09-12T15:00:49.619+0000] {taskinstance.py:1412} INFO - Marking task as UP_FOR_RETRY. dag_id=first_dag, task_id=get_data, execution_date=20220912T150047, start_date=20220912T150049, end_date=20220912T150049
[2022-09-12T15:00:49.645+0000] {standard_task_runner.py:97} ERROR - Failed to execute job 38 for task get_data ([Errno 2] No such file or directory: 'data/DATA.csv'; 229)
[2022-09-12T15:00:49.678+0000] {local_task_job.py:156} INFO - Task exited with return code 1
[2022-09-12T15:00:49.746+0000] {local_task_job.py:279} INFO - 0 downstream tasks scheduled from follow-on schedule check
